pip list
devcontainer.jsonをかいて
docker fileを書いたからうまく行ったみたい

root@67bb2f216231:/workspaces/dango_sample_app# django-admin  startproject djangopj .

Nginxの設定とDockerfile自体は基本的には問題ないように見えますが、いくつかの点を確認してみましょう。

コンテナ間の名前解決: docker-compose.ymlでDjango（Gunicorn）を動かすサービスの名前がappである必要があります。Nginxの設定（default.conf）でupstream djangoセクションでserver app:8000;とありますので、このappはDjango（Gunicorn）のサービス名と一致していなければなりません。

静的ファイル: location /static/でalias /static/;とありますが、この/static/はコンテナ内でDjangoが静的ファイルを保存する場所と一致している必要があります。Djangoのsettings.pyでSTATIC_ROOTがどう設定されているかによります。

docker-compose.ymlの更新: Nginxのサービスをdocker-compose.ymlに追加する必要があります。

例:

yml
Copy code
version: '3'
services:
  web: # この名前がappと同じであれば問題ありません。そうでなければ、Nginxの設定を更新する必要があります。
    build: ./web
    ...
  nginx:
    build: ./containers/nginx
    ports:
      - "80:80"
    depends_on:
      - web # Nginxがwebサービス（Django/Gunicorn）に依存していることを明示
  ...
パスとボリューム: Dockerfileや設定ファイルがある場所を正確に指定する必要があります。例えば、COPY containers/nginx/conf.d/default.conf /etc/nginx/conf.d/default.confのcontainers/nginx/conf.d/default.confはDockerfileがある場所からの相対パスまたは絶対パスでなければなりません。
これらの点を確認・調整した後、全体の設定が適切であれば問題なく動作するはずです。

.devcontainer.jsonを変更した

// For format details, see https://aka.ms/devcontainer.json. For config options, see the
// README at: https://github.com/devcontainers/templates/tree/main/src/docker-existing-dockerfile
{
	"name": "Existing Dockerfile",
	"build": {
		// Sets the run context to one level up instead of the .devcontainer folder.
		"context": "..",
		// Update the 'dockerFile' property if you aren't using the standard 'Dockerfile' filename.
		"dockerfile": "../web/Dockerfile"
	}

	// Features to add to the dev container. More info: https://containers.dev/features.
	// "features": {},

	// Use 'forwardPorts' to make a list of ports inside the container available locally.
	// "forwardPorts": [],

	// Uncomment the next line to run commands after the container is created.
	// "postCreateCommand": "cat /etc/os-release",

	// Configure tool-specific properties.
	// "customizations": {},

	// Uncomment to connect as an existing user other than the container default. More info: https://aka.ms/dev-containers-non-root.
	// "remoteUser": "devcontainer"
}


ttyオプションについて
tty: trueはコンテナ内でTTY（端末）を確保するためのオプションです。開発環境でのデバッグや対話的な作業を容易にするためによく使われますが、本番環境で必要かどうかはケースによります。多くの場合、本番環境ではこのオプションは不要です。実際には、本番環境でアプリケーションを稼働させる場合、GunicornやuWSGIなどのWSGIサーバがその役割を果たすため、TTYは通常不要です。

root@a9013a118b75:/workspaces/dango_sample_app# django-admin startproject T2 .

はい、その通りです。`web/`ディレクトリ内にDjangoプロジェクトやアプリケーションを作成すると、そのディレクトリが`docker-compose.yml`で設定されている`web`サービスのコンテナ内で`/app`としてマウントされます。これによって、コンテナ内でDjangoプロジェクトやアプリケーションが適切に動作するようになります。

具体的な手順としては、以下のように行えます。

1. `web/`ディレクトリに移動します。
    ```bash
    cd web
    ```
   
2. そのディレクトリ内でDjangoプロジェクトを作成します。
    ```bash
    django-admin startproject my_project
    ```

3. 必要に応じて、Djangoアプリケーションも作成します。
    ```bash
    python manage.py startapp my_app
    ```

この構成により、`docker-compose up`コマンドを実行すると、`web`サービスのコンテナ内でDjangoプロジェクトとアプリケーションが`/app`ディレクトリにマウントされ、`gunicorn`などのWSGIサーバーがそれをホストします。

現状のディレクトリ構成は以下のようになります。
django_sample_app/
├──.devcontainer/
└── devcontainer.json
├── docker-compose.yml
├── web/
│   └── dockerfile
│   └──manage.py
│   └── T2/
│       └──__init__.py
│       └──asgi.py
│       └──settings.py
│       └──urls.py
│       └──wsgi.py
├── nginx/
│   └── dockerfile
│   └── conf.d/
│         └──default.conf


 build: 
      context: .
      dockerfile: containes/django/Dockerfile
に設定すると
django_prod/containers/django/dockerfile
が
django_prod/docker-compose.prod.ymlから見えるということでしょうか？？

ChatGPT
docker-compose.prod.yml ファイルが django_prod ディレクトリ内にある場合、以下のようなディレクトリ構造を想定しています。

Copy code
django_prod/
├── containers/
│   └── django/
│       └── Dockerfile
└── docker-compose.prod.yml
この状況で docker-compose.prod.yml 内に

yaml
Copy code
build: 
  context: .
  dockerfile: containers/django/Dockerfile
と設定されている場合、context: . は docker-compose.prod.yml がある django_prod ディレクトリをビルドコンテキスト（作業ディレクトリ）として指定します。そのため、dockerfile: containers/django/Dockerfile はこのビルドコンテキストを基に相対パスで指定されています。

結論として、はい、django_prod/containers/django/Dockerfile は django_prod/docker-compose.prod.yml から見える設定になっています。この設定により、Docker は django_prod ディレクトリをビルドコンテキストとして、その中の containers/django/Dockerfile を用いてイメージをビルドします。

https://qiita.com/grv2688/items/47fe1a145b2ca0319287
これで一応動いた

OperationalError at /occupancy_rate/
connection to server at "db" (172.29.0.2), port 5432 failed: FATAL:  database "django_sample" does not exist
Request Method:	GET
Request URL:	http://gunicorn-django/occupancy_rate/
Django Version:	4.2.5
Exception Type:	OperationalError
Exception Value:	
connection to server at "db" (172.29.0.2), port 5432 failed: FATAL:  database "django_sample" does not exist
Exception Location:	/usr/local/lib/python3.11/site-packages/psycopg2/__init__.py, line 122, in connect
Raised during:	occupancy_rate.views.MachineDataView
Python Executable:	/usr/local/bin/python
Python Version:	3.11.5
Python Path:	
['/code',
 '/usr/local/bin',
 '/usr/local/lib/python311.zip',
 '/usr/local/lib/python3.11',
 '/usr/local/lib/python3.11/lib-dynload',
 '/usr/local/lib/python3.11/site-packages']
Server time:	Fri, 22 Sep 2023 11:27:12 +0000


dbとうまく行ってないらしい
make migrationとかその他諸々実行していない


root@06ca5b13b853:/code# python manage.py makemigrations
/usr/local/lib/python3.11/site-packages/django/core/management/commands/makemigrations.py:158: RuntimeWarning: Got an error checking a consistent migration history performed for database connection 'default': connection to server at "db" (172.29.0.2), port 5432 failed: FATAL:  database "django_sample" does not exist

  warnings.warn(
No changes detected
root@06ca5b13b853:/code# python manage.py migrate occupancy_rate
Traceback (most recent call last):
  File "/usr/local/lib/python3.11/site-packages/django/db/backends/base/base.py", line 289, in ensure_connection
    self.connect()
  File "/usr/local/lib/python3.11/site-packages/django/utils/asyncio.py", line 26, in inner
    return func(*args, **kwargs)
           ^^^^^^^^^^^^^^^^^^^^^
  File "/usr/local/lib/python3.11/site-packages/django/db/backends/base/base.py", line 270, in connect
    self.connection = self.get_new_connection(conn_params)
                      ^^^^^^^^^^^^^^^^^^^^^^^^^^^^^^^^^^^^
  File "/usr/local/lib/python3.11/site-packages/django/utils/asyncio.py", line 26, in inner
    return func(*args, **kwargs)
           ^^^^^^^^^^^^^^^^^^^^^
  File "/usr/local/lib/python3.11/site-packages/django/db/backends/postgresql/base.py", line 275, in get_new_connection
    connection = self.Database.connect(**conn_params)
                 ^^^^^^^^^^^^^^^^^^^^^^^^^^^^^^^^^^^^
  File "/usr/local/lib/python3.11/site-packages/psycopg2/__init__.py", line 122, in connect
    conn = _connect(dsn, connection_factory=connection_factory, **kwasync)
           ^^^^^^^^^^^^^^^^^^^^^^^^^^^^^^^^^^^^^^^^^^^^^^^^^^^^^^^^^^^^^^^
psycopg2.OperationalError: connection to server at "db" (172.29.0.2), port 5432 failed: FATAL:  database "django_sample" does not exist


The above exception was the direct cause of the following exception:

Traceback (most recent call last):
  File "/code/manage.py", line 22, in <module>
    main()
  File "/code/manage.py", line 18, in main
    execute_from_command_line(sys.argv)
  File "/usr/local/lib/python3.11/site-packages/django/core/management/__init__.py", line 442, in execute_from_command_line
    utility.execute()
  File "/usr/local/lib/python3.11/site-packages/django/core/management/__init__.py", line 436, in execute
    self.fetch_command(subcommand).run_from_argv(self.argv)
  File "/usr/local/lib/python3.11/site-packages/django/core/management/base.py", line 412, in run_from_argv
    self.execute(*args, **cmd_options)
  File "/usr/local/lib/python3.11/site-packages/django/core/management/base.py", line 458, in execute
    output = self.handle(*args, **options)
             ^^^^^^^^^^^^^^^^^^^^^^^^^^^^^
  File "/usr/local/lib/python3.11/site-packages/django/core/management/base.py", line 106, in wrapper
    res = handle_func(*args, **kwargs)
          ^^^^^^^^^^^^^^^^^^^^^^^^^^^^
  File "/usr/local/lib/python3.11/site-packages/django/core/management/commands/migrate.py", line 117, in handle
    executor = MigrationExecutor(connection, self.migration_progress_callback)
               ^^^^^^^^^^^^^^^^^^^^^^^^^^^^^^^^^^^^^^^^^^^^^^^^^^^^^^^^^^^^^^^
  File "/usr/local/lib/python3.11/site-packages/django/db/migrations/executor.py", line 18, in __init__
    self.loader = MigrationLoader(self.connection)
                  ^^^^^^^^^^^^^^^^^^^^^^^^^^^^^^^^
  File "/usr/local/lib/python3.11/site-packages/django/db/migrations/loader.py", line 58, in __init__
    self.build_graph()
  File "/usr/local/lib/python3.11/site-packages/django/db/migrations/loader.py", line 235, in build_graph
    self.applied_migrations = recorder.applied_migrations()
                              ^^^^^^^^^^^^^^^^^^^^^^^^^^^^^
  File "/usr/local/lib/python3.11/site-packages/django/db/migrations/recorder.py", line 81, in applied_migrations
    if self.has_table():
       ^^^^^^^^^^^^^^^^
  File "/usr/local/lib/python3.11/site-packages/django/db/migrations/recorder.py", line 57, in has_table
    with self.connection.cursor() as cursor:
         ^^^^^^^^^^^^^^^^^^^^^^^^
  File "/usr/local/lib/python3.11/site-packages/django/utils/asyncio.py", line 26, in inner
    return func(*args, **kwargs)
           ^^^^^^^^^^^^^^^^^^^^^
  File "/usr/local/lib/python3.11/site-packages/django/db/backends/base/base.py", line 330, in cursor
    return self._cursor()
           ^^^^^^^^^^^^^^
  File "/usr/local/lib/python3.11/site-packages/django/db/backends/base/base.py", line 306, in _cursor
    self.ensure_connection()
  File "/usr/local/lib/python3.11/site-packages/django/utils/asyncio.py", line 26, in inner
    return func(*args, **kwargs)
           ^^^^^^^^^^^^^^^^^^^^^
  File "/usr/local/lib/python3.11/site-packages/django/db/backends/base/base.py", line 288, in ensure_connection
    with self.wrap_database_errors:
  File "/usr/local/lib/python3.11/site-packages/django/db/utils.py", line 91, in __exit__
    raise dj_exc_value.with_traceback(traceback) from exc_value
  File "/usr/local/lib/python3.11/site-packages/django/db/backends/base/base.py", line 289, in ensure_connection
    self.connect()
  File "/usr/local/lib/python3.11/site-packages/django/utils/asyncio.py", line 26, in inner
    return func(*args, **kwargs)
           ^^^^^^^^^^^^^^^^^^^^^
  File "/usr/local/lib/python3.11/site-packages/django/db/backends/base/base.py", line 270, in connect
    self.connection = self.get_new_connection(conn_params)
                      ^^^^^^^^^^^^^^^^^^^^^^^^^^^^^^^^^^^^
  File "/usr/local/lib/python3.11/site-packages/django/utils/asyncio.py", line 26, in inner
    return func(*args, **kwargs)
           ^^^^^^^^^^^^^^^^^^^^^
  File "/usr/local/lib/python3.11/site-packages/django/db/backends/postgresql/base.py", line 275, in get_new_connection
    connection = self.Database.connect(**conn_params)
                 ^^^^^^^^^^^^^^^^^^^^^^^^^^^^^^^^^^^^
  File "/usr/local/lib/python3.11/site-packages/psycopg2/__init__.py", line 122, in connect
    conn = _connect(dsn, connection_factory=connection_factory, **kwasync)
           ^^^^^^^^^^^^^^^^^^^^^^^^^^^^^^^^^^^^^^^^^^^^^^^^^^^^^^^^^^^^^^^
django.db.utils.OperationalError: connection to server at "db" (172.29.0.2), port 5432 failed: FATAL:  database "django_sample" does not exist

root@06ca5b13b853:/code# 